Workbook

Sheet Sales_by Inv No & by custom WSK
A3: Sum of Sales Amount | D3: Year (Sales) | E3: Period (Sales) | Z3: Sum of Sales Amount | AC3: Year (Sales) | AD3: Period (Sales)
D4: 2022 | P4: 2022 Total | Q4: Grand Total | AC4: 2022 | AK4: 2022 Total | AL4: Grand Total
A5: Customer Name | B5: Invoice No | C5: Invoice Date | D5: 6 | E5: 7 | F5: 8 | G5: 9 | H5: 10 | I5: 11 | J5: 12 | K5: 1 | L5: 2 | M5: 3 | N5: 4 | O5: 5 | Z5: Customer Name | AA5: Invoice No | AB5: Invoice Date | AC5: 6 | AD5: 7 | AE5: 8 | AF5: 1 | AG5: 2 | AH5: 3 | AI5: 4 | AJ5: 5
A6: WSK Tanks Sdn Bhd | B6: INV00000182 | C6: 44564 | K6: 8273 | P6: 8273 | Q6: 8273 | Z6: Yew Seng Gardening Supply Sdn Bhd | AA6: INV00000187 | AB6: 44572 | AF6: 15346 | AK6: 15346 | AL6: 15346
B7: INV00000184 | C7: 44568 | K7: 1233 | P7: 1233 | Q7: 1233 | AA7: INV00000195 | AB7: 44585 | AF7: 13474 | AK7: 13474 | AL7: 13474
B8: INV00000185 | C8: 44569 | K8: 7377 | P8: 7377 | Q8: 7377 | AA8: INV00000200 | AB8: 44609 | AG8: 14395 | AK8: 14395 | AL8: 14395
B9: INV00000189 | C9: 44574 | K9: 28549 | P9: 28549 | Q9: 28549 | AA9: INV00000211 | AB9: 44628 | AH9: 15280 | AK9: 15280 | AL9: 15280
B10: INV00000193 | C10: 44579 | K10: 11502 | P10: 11502 | Q10: 11502 | AA10: INV00000217 | AB10: 44635 | AH10: 14185 | AK10: 14185 | AL10: 14185
B11: INV00000206 | C11: 44616 | L11: 7961 | P11: 7961 | Q11: 7961 | AA11: INV00000251 | AB11: 44678 | AI11: 11160 | AK11: 11160 | AL11: 11160
B12: INV00000207 | C12: 44618 | L12: 2678 | P12: 2678 | Q12: 2678 | AA12: INV00000272 | AB12: 44704 | AJ12: 14715 | AK12: 14715 | AL12: 14715
B13: INV00000216 | C13: 44634 | M13: 3029 | P13: 3029 | Q13: 3029 | AA13: INV00000282 | AB13: 44721 | AC13: 12690 | AK13: 12690 | AL13: 12690
B14: INV00000218 | C14: 44635 | M14: 11425 | P14: 11425 | Q14: 11425 | AA14: INV00000294 | AB14: 44741 | AC14: 18515 | AK14: 18515 | AL14: 18515
B15: INV00000220 | C15: 44638 | M15: 9888 | P15: 9888 | Q15: 9888 | AA15: INV00000303 | AB15: 44768 | AD15: 13445 | AK15: 13445 | AL15: 13445
B16: INV00000223 | C16: 44643 | M16: 8819 | P16: 8819 | Q16: 8819 | AA16: INV00000318 | AB16: 44798 | AE16: 15671 | AK16: 15671 | AL16: 15671
B17: INV00000224 | C17: 44645 | M17: 14422 | P17: 14422 | Q17: 14422 | Z17: Yew Seng Gardening Supply Sdn Bhd Total | AC17: 31205 | AD17: 13445 | AE17: 15671 | AF17: 28820 | AG17: 14395 | AH17: 29465 | AI17: 11160 | AJ17: 14715 | AK17: 158876 | AL17: 158876
B18: INV00000226 | C18: 44649 | M18: 7593 | P18: 7593 | Q18: 7593 | Z18: Grand Total | AC18: 31205 | AD18: 13445 | AE18: 15671 | AF18: 28820 | AG18: 14395 | AH18: 29465 | AI18: 11160 | AJ18: 14715 | AK18: 158876 | AL18: 158876
B19: INV00000229 | C19: 44652 | N19: 9157.5 | P19: 9157.5 | Q19: 9157.5
B20: INV00000231 | C20: 44656 | N20: 10497.5 | P20: 10497.5 | Q20: 10497.5
B21: INV00000235 | C21: 44660 | N21: 8569.5 | P21: 8569.5 | Q21: 8569.5
B22: INV00000239 | C22: 44664 | N22: 10975.5 | P22: 10975.5 | Q22: 10975.5
B23: INV00000242 | C23: 44667 | N23: 10103.5 | P23: 10103.5 | Q23: 10103.5
B24: INV00000244 | C24: 44670 | N24: 3076 | P24: 3076 | Q24: 3076
B25: INV00000249 | C25: 44674 | N25: 11151 | P25: 11151 | Q25: 11151
B26: INV00000253 | C26: 44679 | N26: 11858.5 | P26: 11858.5 | Q26: 11858.5
B27: INV00000256 | C27: 44681 | N27: 15244 | P27: 15244 | Q27: 15244
B28: INV00000257 | C28: 44687 | O28: 11530 | P28: 11530 | Q28: 11530
B29: INV00000259 | C29: 44688 | O29: 16245 | P29: 16245 | Q29: 16245
B30: INV00000265 | C30: 44695 | O30: 10369.5 | P30: 10369.5 | Q30: 10369.5
B31: INV00000267 | C31: 44699 | O31: 8417 | P31: 8417 | Q31: 8417
B32: INV00000269 | C32: 44701 | O32: 13110 | P32: 13110 | Q32: 13110
B33: INV00000271 | C33: 44702 | O33: 13110 | P33: 13110 | Q33: 13110
B34: INV00000273 | C34: 44704 | O34: 6750 | P34: 6750 | Q34: 6750
B35: INV00000276 | C35: 44706 | O35: 14068 | P35: 14068 | Q35: 14068
B36: INV00000278 | C36: 44714 | D36: 12427 | P36: 12427 | Q36: 12427
B37: INV00000280 | C37: 44716 | D37: 9000 | P37: 9000 | Q37: 9000
B38: INV00000285 | C38: 44723 | D38: 4950 | P38: 4950 | Q38: 4950
B39: INV00000289 | C39: 44730 | D39: 4431.5 | P39: 4431.5 | Q39: 4431.5
B40: INV00000292 | C40: 44736 | D40: 5889 | P40: 5889 | Q40: 5889
B41: INV00000297 | C41: 44756 | E41: 12855.5 | P41: 12855.5 | Q41: 12855.5
B42: INV00000299 | C42: 44760 | E42: 9153 | P42: 9153 | Q42: 9153
...

Sheet Customer Aging
A1: Customer Aging
A2: Month : As of July 2025
A4: Sum of Outstanding | B4: Term | W4: Sum of Outstanding | AB4: Term | AR4: Sum of Outstanding | AU4: Term
A5: Customer Name | B5: 0 | C5: 45 | D5: 60 | E5: 120 | F5: #N/A | G5: 30 | H5: Grand Total | W5: Customer Name | X5: Year (Due) | Y5: Period (Due) | Z5: Invoice Date | AA5: Invoice No | AB5: 0 | AC5: 45 | AD5: 60 | AE5: 120 | AF5: #N/A | AG5: 30 | AH5: Grand Total | AR5: Customer Name | AS5: Year (Due) | AT5: Period (Due) | AU5: 0 | AV5: 45 | AW5: 60 | AX5: 120 | AY5: #N/A | AZ5: 30 | BA5: Grand Total
A6: Artscene Creative | B6: 0 | H6: 0 | W6: Artscene Creative | X6: 2020 | Y6: 8 | Z6: 44053 | AA6: INV2020/00000012 | AB6: 0 | AH6: 0 | AR6: Artscene Creative | AS6: 2020 | AT6: 8 | AU6: 0 | BA6: 0
A7: Chin Fibreglass (M) Sdn Bhd | B7: 0 | H7: 0 | Y7: 10 | Z7: 44109 | AA7: INV2020/00000033 | AB7: 0 | AH7: 0 | AT7: 10 | AU7: 0 | BA7: 0
A8: JMC Steel Engineering Sdn Bhd | D8: 0 | H8: 0 | Z8: 44123 | AA8: INV2020/00000042 | AB8: 0 | AH8: 0 | AT8: 11 | AU8: 0 | BA8: 0
A9: Kelnico Marketing | B9: 0 | H9: 0 | Z9: 44125 | AA9: INV2020/00000043 | AB9: 0 | AH9: 0 | AS9: 2021 | AT9: 2 | AU9: 0 | BA9: 0
A10: Pandian Art Gallery Manufacturing | C10: 1277.5 | H10: 1277.5 | Z10: 44135 | AA10: INV2020/00000047 | AB10: 0 | AH10: 0 | AT10: 5 | AU10: 0 | BA10: 0
A11: Perniagaan Fibra Sahih | B11: 0.2 | H11: 0.2 | Y11: 11 | Z11: 44145 | AA11: INV2020/00000050 | AB11: 0 | AH11: 0 | AT11: 9 | AU11: 0 | BA11: 0
A12: Siew Min Lorry Sdn Bhd | E12: 0 | H12: 0 | Z12: 44158 | AA12: INV2020/00000056 | AB12: 0 | AH12: 0 | AT12: 10 | AU12: 0 | BA12: 0
A13: Sley | B13: 0 | H13: 0 | X13: 2021 | Y13: 2 | Z13: 44229 | AA13: INV2020/00000078 | AB13: 0 | AH13: 0 | AT13: 11 | AU13: 0 | BA13: 0
A14: Wonderland Design Productions Studio | B14: 0 | H14: 0 | Z14: 44244 | AA14: INV2020/00000081 | AB14: 0 | AH14: 0 | AS14: 2024 | AT14: 10 | AU14: 0 | BA14: 0
A15: Yew Seng Gardening Supply Sdn Bhd | E15: 52482.9 | H15: 52482.9 | Y15: 5 | Z15: 44322 | AA15: INV00000103 | AB15: 0 | AH15: 0 | AT15: 11 | AU15: 0 | BA15: 0
A16: JT Johan Sdn Bhd | B16: 0 | H16: 0 | Z16: 44335 | AA16: INV00000105 | AB16: 0 | AH16: 0 | AR16: Artscene Creative Total | AU16: 0 | BA16: 0
A17: Cash - Muhammad Syahin Bin | F17: 0 | H17: 0 | Z17: 44341 | AA17: INV00000107 | AB17: 0 | AH17: 0 | AR17: Chin Fibreglass (M) Sdn Bhd | AS17: 2020 | AT17: 8 | AU17: 0 | BA17: 0
A18: Cash - PMC | F18: 0 | H18: 0 | Y18: 9 | Z18: 44440 | AA18: INV00000113 | AB18: 0 | AH18: 0 | AT18: 10 | AU18: 0 | BA18: 0
A19: IK Fibre Glass Enterprise | B19: 0 | H19: 0 | AA19: INV00000114 | AB19: 0 | AH19: 0 | AR19: Chin Fibreglass (M) Sdn Bhd Total | AU19: 0 | BA19: 0
A20: S&J Business Solutions | B20: 0 | H20: 0 | Z20: 44467 | AA20: INV00000122 | AB20: 0 | AH20: 0 | AR20: JMC Steel Engineering Sdn Bhd | AS20: 2020 | AT20: 10 | AW20: 0 | BA20: 0
A21: Win Fiber Sdn Bhd | B21: 0 | H21: 0 | Y21: 10 | Z21: 44484 | AA21: INV00000137 | AB21: 0 | AH21: 0 | AS21: 2021 | AT21: 1 | AW21: 0 | BA21: 0
A22: Living Divani (M) Sdn Bhd | B22: 0 | H22: 0 | Y22: 11 | Z22: 44501 | AA22: INV00000150 | AB22: 0 | AH22: 0 | AT22: 5 | AW22: 0 | BA22: 0
A23: Desuki Affela Empire Enterprise | B23: 96862.3 | H23: 96862.3 | X23: 2024 | Y23: 10 | Z23: 45582 | AA23: INV00001000 | AB23: 0 | AH23: 0 | AT23: 6 | AW23: 0 | BA23: 0
A24: WSK Tanks Sdn Bhd | B24: 4.5474735e-13 | H24: 4.5474735e-13 | Y24: 11 | Z24: 45600 | AA24: INV00001020 | AB24: 0 | AH24: 0 | AT24: 7 | AW24: 0 | BA24: 0
A25: Cash - En Mat | F25: 0 | H25: 0 | W25: Artscene Creative Total | AB25: 0 | AH25: 0 | AT25: 12 | AW25: 0 | BA25: 0
A26: KT Profesional Fiber | B26: 28583.6 | H26: 28583.6 | W26: Chin Fibreglass (M) Sdn Bhd | X26: 2020 | Y26: 8 | Z26: 44065 | AA26: INV2020/00000018 | AB26: 0 | AH26: 0 | AS26: 2022 | AT26: 6 | AW26: 0 | BA26: 0
A27: SF Engineering Solution | B27: 514.2 | H27: 514.2 | Y27: 10 | Z27: 44118 | AA27: INV2020/00000038 | AB27: 0 | AH27: 0 | AT27: 7 | AW27: 0 | BA27: 0
A28: Bestway Engineering Solutions | B28: 0 | H28: 0 | Z28: 44123 | AA28: INV2020/00000038 | AB28: 0 | AH28: 0 | AT28: 8 | AW28: 0 | BA28: 0
A29: LLL Automotive Sdn Bhd | B29: 0 | H29: 0 | W29: Chin Fibreglass (M) Sdn Bhd Total | AB29: 0 | AH29: 0 | AT29: 9 | AW29: 0 | BA29: 0
A30: Worldwide Competence Sdn Bhd | B30: 0 | H30: 0 | W30: JMC Steel Engineering Sdn Bhd | X30: 2020 | Y30: 10 | Z30: 44068 | AA30: INV2020/00000021 | AD30: 0 | AH30: 0 | AT30: 10 | AW30: 0 | BA30: 0
A31: Megapower Service | B31: 0 | H31: 0 | X31: 2021 | Y31: 1 | Z31: 44146 | AA31: INV2020/00000051 | AD31: 0 | AH31: 0 | AT31: 11 | AW31: 0 | BA31: 0
A32: Transform Star Sdn Bhd | B32: 33600.6 | H32: 33600.6 | Z32: 44163 | AA32: INV2020/00000060 | AD32: 0 | AH32: 0 | AT32: 12 | AW32: 0 | BA32: 0
A33: Cash - Vinz Yew Kok Wah | B33: 0 | H33: 0 | Y33: 5 | Z33: 44266 | AA33: INV00000088 | AD33: 0 | AH33: 0 | AT33: 4 | AW33: 0 | BA33: 0
A34: CANCELLED INVOICE | F34: 0 | H34: 0 | Z34: 44279 | AA34: INV00000091 | AD34: 0 | AH34: 0 | AS34: 2023 | AT34: 1 | AW34: 0 | BA34: 0
A35: Cash - Big Jackfruit Trading | B35: 0 | H35: 0 | Y35: 6 | Z35: 44313 | AA35: INV00000100 | AD35: 0 | AH35: 0 | AT35: 2 | AW35: 0 | BA35: 0
A36: Hai Kee Hung Sdn Bhd | B36: 0 | H36: 0 | Y36: 7 | Z36: 44348 | AA36: INV00000109 | AD36: 0 | AH36: 0 | AT36: 3 | AW36: 0 | BA36: 0
A37: Cash - Zaina | B37: 0 | H37: 0 | AA37: INV00000110 | AD37: 0 | AH37: 0 | AT37: 5 | AW37: 0 | BA37: 0
A38: Cash - Zaidi | B38: 0 | H38: 0 | Y38: 12 | Z38: 44483 | AA38: INV00000135 | AD38: 0 | AH38: 0 | AT38: 6 | AW38: 0 | BA38: 0
A39: Cash - ZTY Fibre | B39: 2576.3 | H39: 2576.3 | X39: 2022 | Y39: 6 | Z39: 44660 | AA39: INV00000234 | AD39: 0 | AH39: 0 | AT39: 7 | AW39: 0 | BA39: 0
A40: Cash - MLGaia Enterprise | B40: 0 | H40: 0 | Y40: 7 | Z40: 44691 | AA40: INV00000260 | AD40: 0 | AH40: 0 | AT40: 8 | AW40: 0 | BA40: 0
A41: Choi Fook Sing Enterprise Sdn Bhd | B41: 0 | H41: 0 | Y41: 8 | Z41: 44726 | AA41: INV00000287 | AD41: 0 | AH41: 0 | AT41: 9 | AW41: 0 | BA41: 0
...

Sheet Raw Sales
A1: Invoice Date | B1: Period (Sales) | C1: Year (Sales) | D1: Invoice No | E1: Customer Code | F1: Customer Name | G1: Product | H1: Qty | I1: Payment Term | J1: Term | K1: Due date | L1: Period (Due) | M1: Year (Due) | N1: Sales Amount | O1: Collection | P1: Outstanding | Q1: Total Sales | R1: Payment mode | S1: Remark | T1: Remark2
A2: 43822 | B2: =MONTH(A2) -> 12 | C2: =YEAR(A2) -> 2019 | D2: INV2019/00000001 | E2: =VLOOKUP(F2,'Set up'!$A$2:$C$70,2,FALSE) -> C00000001 | F2: Kelnico Marketing | G2: RA Resin SHCP 268W (225kg) | H2: 1 | I2: =VLOOKUP(F2,'Set up'!$A$2:$C$70,3,FALSE) -> Cash | J2: =VLOOKUP(F2,'Set up'!$A$2:$D$70,4,FALSE) -> 0 | K2: =A2+J2 -> 43822 | L2: =MONTH(K2) -> 12 | M2: =YEAR(K2) -> 2019 | N2: 1530 | O2: =SUM(-N2) -> -1530 | P2: =SUM(N2+O2) -> 0 | Q2: =N2 -> 1530 | R2: =VLOOKUP(F2,'Set up'!$A$2:$E$70,5,FALSE) -> Trsf | S2: Trsf 29/5
A3: 43822 | B3: =MONTH(A3) -> 12 | C3: =YEAR(A3) -> 2019 | D3: INV2019/00000001 | E3: =VLOOKUP(F3,'Set up'!$A$2:$C$70,2,FALSE) -> C00000001 | F3: Kelnico Marketing | G3: RA CSM 450 GSM JUSHI 37kg 79m(L) X 1040mm(W) | H3: 6 | I3: =VLOOKUP(F3,'Set up'!$A$2:$C$70,3,FALSE) -> Cash | J3: =VLOOKUP(F3,'Set up'!$A$2:$D$70,4,FALSE) -> 0 | K3: =A3+J3 -> 43822 | L3: =MONTH(K3) -> 12 | M3: =YEAR(K3) -> 2019 | N3: 1443 | O3: =SUM(-N3) -> -1443 | P3: =SUM(N3+O3) -> 0 | Q3: =SUM(Q2+N3) -> 2973 | R3: =VLOOKUP(F3,'Set up'!$A$2:$E$70,5,FALSE) -> Trsf | S3: Trsf 29/5
A4: 43984 | B4: =MONTH(A4) -> 6 | C4: =YEAR(A4) -> 2020 | D4: INV2020/00000002 | E4: =VLOOKUP(F4,'Set up'!$A$2:$C$70,2,FALSE) -> C00000001 | F4: Kelnico Marketing | G4: RA Gelcoat GS-S ISO (20kg) | H4: 2 | I4: =VLOOKUP(F4,'Set up'!$A$2:$C$70,3,FALSE) -> Cash | J4: =VLOOKUP(F4,'Set up'!$A$2:$D$70,4,FALSE) -> 0 | K4: =A4+J4 -> 43984 | L4: =MONTH(K4) -> 6 | M4: =YEAR(K4) -> 2020 | N4: 480 | O4: =SUM(-N4) -> -480 | P4: =SUM(N4+O4) -> 0 | Q4: =SUM(Q3+N4) -> 3453 | R4: =VLOOKUP(F4,'Set up'!$A$2:$E$70,5,FALSE) -> Trsf | S4: Trsf 24/6
A5: 43993 | B5: =MONTH(A5) -> 6 | C5: =YEAR(A5) -> 2020 | D5: INV2020/00000003 | E5: =VLOOKUP(F5,'Set up'!$A$2:$C$70,2,FALSE) -> C00000002 | F5: Sley | G5: RA Resin SHCP 268W (225Kg) | H5: 1 | I5: =VLOOKUP(F5,'Set up'!$A$2:$C$70,3,FALSE) -> Cash | J5: =VLOOKUP(F5,'Set up'!$A$2:$D$70,4,FALSE) -> 0 | K5: =A5+J5 -> 43993 | L5: =MONTH(K5) -> 6 | M5: =YEAR(K5) -> 2020 | N5: 1395 | O5: =SUM(-N5) -> -1395 | P5: =SUM(N5+O5) -> 0 | Q5: =SUM(Q4+N5) -> 4848 | R5: =VLOOKUP(F5,'Set up'!$A$2:$E$70,5,FALSE) -> Chq | S5: Chq 13/6
A6: 43993 | B6: =MONTH(A6) -> 6 | C6: =YEAR(A6) -> 2020 | D6: INV2020/00000003 | E6: =VLOOKUP(F6,'Set up'!$A$2:$C$70,2,FALSE) -> C00000002 | F6: Sley | G6: RB Acetone (160Kg) | H6: 1 | I6: =VLOOKUP(F6,'Set up'!$A$2:$C$70,3,FALSE) -> Cash | J6: =VLOOKUP(F6,'Set up'!$A$2:$D$70,4,FALSE) -> 0 | K6: =A6+J6 -> 43993 | L6: =MONTH(K6) -> 6 | M6: =YEAR(K6) -> 2020 | N6: 672 | O6: =SUM(-N6) -> -672 | P6: =SUM(N6+O6) -> 0 | Q6: =SUM(Q5+N6) -> 5520 | R6: =VLOOKUP(F6,'Set up'!$A$2:$E$70,5,FALSE) -> Chq | S6: Chq 13/6
A7: 43999 | B7: =MONTH(A7) -> 6 | C7: =YEAR(A7) -> 2020 | D7: INV2020/00000004 | E7: =VLOOKUP(F7,'Set up'!$A$2:$C$70,2,FALSE) -> C00000001 | F7: Kelnico Marketing | G7: RA Resin SHCP 268W (225kg) | H7: 1 | I7: =VLOOKUP(F7,'Set up'!$A$2:$C$70,3,FALSE) -> Cash | J7: =VLOOKUP(F7,'Set up'!$A$2:$D$70,4,FALSE) -> 0 | K7: =A7+J7 -> 43999 | L7: =MONTH(K7) -> 6 | M7: =YEAR(K7) -> 2020 | N7: 1530 | O7: =SUM(-N7) -> -1530 | P7: =SUM(N7+O7) -> 0 | Q7: =SUM(Q6+N7) -> 7050 | R7: =VLOOKUP(F7,'Set up'!$A$2:$E$70,5,FALSE) -> Trsf | S7: Trsf 24/6
A8: 43999 | B8: =MONTH(A8) -> 6 | C8: =YEAR(A8) -> 2020 | D8: INV2020/00000004 | E8: =VLOOKUP(F8,'Set up'!$A$2:$C$70,2,FALSE) -> C00000001 | F8: Kelnico Marketing | G8: RA CSM 450 GSM JUSHI 37kg 79m(L) X 1040mm(W) | H8: 3 | I8: =VLOOKUP(F8,'Set up'!$A$2:$C$70,3,FALSE) -> Cash | J8: =VLOOKUP(F8,'Set up'!$A$2:$D$70,4,FALSE) -> 0 | K8: =A8+J8 -> 43999 | L8: =MONTH(K8) -> 6 | M8: =YEAR(K8) -> 2020 | N8: 720 | O8: =SUM(-N8) -> -720 | P8: =SUM(N8+O8) -> 0 | Q8: =SUM(Q7+N8) -> 7770 | R8: =VLOOKUP(F8,'Set up'!$A$2:$E$70,5,FALSE) -> Trsf | S8: Trsf 24/6
A9: 43999 | B9: =MONTH(A9) -> 6 | C9: =YEAR(A9) -> 2020 | D9: INV2020/00000004 | E9: =VLOOKUP(F9,'Set up'!$A$2:$C$70,2,FALSE) -> C00000001 | F9: Kelnico Marketing | G9: RA Butanox M50 (5Kg) | H9: 2 | I9: =VLOOKUP(F9,'Set up'!$A$2:$C$70,3,FALSE) -> Cash | J9: =VLOOKUP(F9,'Set up'!$A$2:$D$70,4,FALSE) -> 0 | K9: =A9+J9 -> 43999 | L9: =MONTH(K9) -> 6 | M9: =YEAR(K9) -> 2020 | N9: 185 | O9: =SUM(-N9) -> -185 | P9: =SUM(N9+O9) -> 0 | Q9: =SUM(Q8+N9) -> 7955 | R9: =VLOOKUP(F9,'Set up'!$A$2:$E$70,5,FALSE) -> Trsf | S9: Trsf 24/6
A10: 44004 | B10: =MONTH(A10) -> 6 | C10: =YEAR(A10) -> 2020 | D10: INV2020/00000005 | E10: =VLOOKUP(F10,'Set up'!$A$2:$C$70,2,FALSE) -> C00000003 | F10: Pandian Art Gallery Manufacturing | G10: RA Resin SHCP 268W (225kg) | H10: 1 | I10: =VLOOKUP(F10,'Set up'!$A$2:$C$70,3,FALSE) -> 45 | J10: =VLOOKUP(F10,'Set up'!$A$2:$D$70,4,FALSE) -> 45 | K10: =A10+J10 -> 44049 | L10: =MONTH(K10) -> 8 | M10: =YEAR(K10) -> 2020 | N10: 1642.5 | O10: =SUM(-N10) -> -1642.5 | P10: =SUM(N10+O10) -> 0 | Q10: =SUM(Q9+N10) -> 9597.5 | R10: =VLOOKUP(F10,'Set up'!$A$2:$E$70,5,FALSE) -> PD Chq | S10: PD chq 8/8, RM1,827.00 & Cash RM0.50
A11: 44004 | B11: =MONTH(A11) -> 6 | C11: =YEAR(A11) -> 2020 | D11: INV2020/00000005 | E11: =VLOOKUP(F11,'Set up'!$A$2:$C$70,2,FALSE) -> C00000003 | F11: Pandian Art Gallery Manufacturing | G11: RA Butanox M50 (5Kg) | H11: 2 | I11: =VLOOKUP(F11,'Set up'!$A$2:$C$70,3,FALSE) -> 45 | J11: =VLOOKUP(F11,'Set up'!$A$2:$D$70,4,FALSE) -> 45 | K11: =A11+J11 -> 44049 | L11: =MONTH(K11) -> 8 | M11: =YEAR(K11) -> 2020 | N11: 185 | O11: =SUM(-N11) -> -185 | P11: =SUM(N11+O11) -> 0 | Q11: =SUM(Q10+N11) -> 9782.5 | R11: =VLOOKUP(F11,'Set up'!$A$2:$E$70,5,FALSE) -> PD Chq | S11: PD chq 8/8, RM1,827.00 & Cash RM0.50
A12: 44013 | B12: =MONTH(A12) -> 7 | C12: =YEAR(A12) -> 2020 | D12: INV2020/00000006 | E12: =VLOOKUP(F12,'Set up'!$A$2:$C$70,2,FALSE) -> C00000004 | F12: Siew Min Lorry Sdn Bhd | G12: RA Gelcoat GP-H (20Kg) | H12: 9 | I12: =VLOOKUP(F12,'Set up'!$A$2:$C$70,3,FALSE) -> 120 | J12: =VLOOKUP(F12,'Set up'!$A$2:$D$70,4,FALSE) -> 120 | K12: =A12+J12 -> 44133 | L12: =MONTH(K12) -> 10 | M12: =YEAR(K12) -> 2020 | N12: 1836 | O12: =SUM(-N12) -> -1836 | P12: =SUM(N12+O12) -> 0 | Q12: =SUM(Q11+N12) -> 11618.5 | R12: =VLOOKUP(F12,'Set up'!$A$2:$E$70,5,FALSE) -> Chq | S12: Chq 16/11/2020
A13: 44026 | B13: =MONTH(A13) -> 7 | C13: =YEAR(A13) -> 2020 | D13: INV2020/00000007 | E13: =VLOOKUP(F13,'Set up'!$A$2:$C$70,2,FALSE) -> C00000003 | F13: Pandian Art Gallery Manufacturing | G13: RA Silicone Rubber (25Kg) | H13: 1 | I13: =VLOOKUP(F13,'Set up'!$A$2:$C$70,3,FALSE) -> 45 | J13: =VLOOKUP(F13,'Set up'!$A$2:$D$70,4,FALSE) -> 45 | K13: =A13+J13 -> 44071 | L13: =MONTH(K13) -> 8 | M13: =YEAR(K13) -> 2020 | N13: 1200 | O13: =SUM(-N13) -> -1200 | P13: =SUM(N13+O13) -> 0 | Q13: =SUM(Q12+N13) -> 12818.5 | R13: =VLOOKUP(F13,'Set up'!$A$2:$E$70,5,FALSE) -> PD Chq | S13: PD chq 16/8
A14: 44027 | B14: =MONTH(A14) -> 7 | C14: =YEAR(A14) -> 2020 | D14: INV2020/00000008 | E14: =VLOOKUP(F14,'Set up'!$A$2:$C$70,2,FALSE) -> C00000001 | F14: Kelnico Marketing | G14: RA Nor 3338W (220Kg) | H14: 1 | I14: =VLOOKUP(F14,'Set up'!$A$2:$C$70,3,FALSE) -> Cash | J14: =VLOOKUP(F14,'Set up'!$A$2:$D$70,4,FALSE) -> 0 | K14: =A14+J14 -> 44027 | L14: =MONTH(K14) -> 7 | M14: =YEAR(K14) -> 2020 | N14: 1496 | O14: =SUM(-N14) -> -1496 | P14: =SUM(N14+O14) -> 0 | Q14: =SUM(Q13+N14) -> 14314.5 | R14: =VLOOKUP(F14,'Set up'!$A$2:$E$70,5,FALSE) -> Trsf | S14: Trsf 28/7
A15: 44027 | B15: =MONTH(A15) -> 7 | C15: =YEAR(A15) -> 2020 | D15: INV2020/00000008 | E15: =VLOOKUP(F15,'Set up'!$A$2:$C$70,2,FALSE) -> C00000001 | F15: Kelnico Marketing | G15: RA Butanox M50 (5Kg) | H15: 4 | I15: =VLOOKUP(F15,'Set up'!$A$2:$C$70,3,FALSE) -> Cash | J15: =VLOOKUP(F15,'Set up'!$A$2:$D$70,4,FALSE) -> 0 | K15: =A15+J15 -> 44027 | L15: =MONTH(K15) -> 7 | M15: =YEAR(K15) -> 2020 | N15: 370 | O15: =SUM(-N15) -> -370 | P15: =SUM(N15+O15) -> 0 | Q15: =SUM(Q14+N15) -> 14684.5 | R15: =VLOOKUP(F15,'Set up'!$A$2:$E$70,5,FALSE) -> Trsf | S15: Trsf 28/7
A16: 44027 | B16: =MONTH(A16) -> 7 | C16: =YEAR(A16) -> 2020 | D16: INV2020/00000008 | E16: =VLOOKUP(F16,'Set up'!$A$2:$C$70,2,FALSE) -> C00000001 | F16: Kelnico Marketing | G16: RC Woven Roving E-800 40Kg 1000mm | H16: 1 | I16: =VLOOKUP(F16,'Set up'!$A$2:$C$70,3,FALSE) -> Cash | J16: =VLOOKUP(F16,'Set up'!$A$2:$D$70,4,FALSE) -> 0 | K16: =A16+J16 -> 44027 | L16: =MONTH(K16) -> 7 | M16: =YEAR(K16) -> 2020 | N16: 232 | O16: =SUM(-N16) -> -232 | P16: =SUM(N16+O16) -> 0 | Q16: =SUM(Q15+N16) -> 14916.5 | R16: =VLOOKUP(F16,'Set up'!$A$2:$E$70,5,FALSE) -> Trsf | S16: Trsf 28/7 | T16: Delivered 22/7/20
A17: 44044 | B17: =MONTH(A17) -> 8 | C17: =YEAR(A17) -> 2020 | D17: INV2020/00000009 | E17: =VLOOKUP(F17,'Set up'!$A$2:$C$70,2,FALSE) -> C00000004 | F17: Siew Min Lorry Sdn Bhd | G17: RA Nor 3338W (220Kg) | H17: 2 | I17: =VLOOKUP(F17,'Set up'!$A$2:$C$70,3,FALSE) -> 120 | J17: =VLOOKUP(F17,'Set up'!$A$2:$D$70,4,FALSE) -> 120 | K17: =A17+J17 -> 44164 | L17: =MONTH(K17) -> 11 | M17: =YEAR(K17) -> 2020 | N17: 2508 | O17: =SUM(-N17) -> -2508 | P17: =SUM(N17+O17) -> 0 | Q17: =SUM(Q16+N17) -> 17424.5 | R17: =VLOOKUP(F17,'Set up'!$A$2:$E$70,5,FALSE) -> Chq | S17: Chq 1/12/2020
A18: 44051 | B18: =MONTH(A18) -> 8 | C18: =YEAR(A18) -> 2020 | D18: INV2020/00000010 | E18: =VLOOKUP(F18,'Set up'!$A$2:$C$70,2,FALSE) -> C00000004 | F18: Siew Min Lorry Sdn Bhd | G18: RA Nor 3338W (220Kg) | H18: 2 | I18: =VLOOKUP(F18,'Set up'!$A$2:$C$70,3,FALSE) -> 120 | J18: =VLOOKUP(F18,'Set up'!$A$2:$D$70,4,FALSE) -> 120 | K18: =A18+J18 -> 44171 | L18: =MONTH(K18) -> 12 | M18: =YEAR(K18) -> 2020 | N18: 2508 | O18: =SUM(-N18) -> -2508 | P18: =SUM(N18+O18) -> 0 | Q18: =SUM(Q17+N18) -> 19932.5 | R18: =VLOOKUP(F18,'Set up'!$A$2:$E$70,5,FALSE) -> Chq | S18: Chq 1/12/2020
A19: 44051 | B19: =MONTH(A19) -> 8 | C19: =YEAR(A19) -> 2020 | D19: INV2020/00000011 | E19: =VLOOKUP(F19,'Set up'!$A$2:$C$70,2,FALSE) -> C00000004 | F19: Siew Min Lorry Sdn Bhd | G19: RA CSM 300 GSM TWL 30kg 64m(L) x 1040mm(W) | H19: 2 | I19: =VLOOKUP(F19,'Set up'!$A$2:$C$70,3,FALSE) -> 120 | J19: =VLOOKUP(F19,'Set up'!$A$2:$D$70,4,FALSE) -> 120 | K19: =A19+J19 -> 44171 | L19: =MONTH(K19) -> 12 | M19: =YEAR(K19) -> 2020 | N19: 324 | O19: =SUM(-N19) -> -324 | P19: =SUM(N19+O19) -> 0 | Q19: =SUM(Q18+N19) -> 20256.5 | R19: =VLOOKUP(F19,'Set up'!$A$2:$E$70,5,FALSE) -> Chq | S19: Chq 1/12/2020
A20: 44053 | B20: =MONTH(A20) -> 8 | C20: =YEAR(A20) -> 2020 | D20: INV2020/00000012 | E20: =VLOOKUP(F20,'Set up'!$A$2:$C$70,2,FALSE) -> C00000005 | F20: Artscene Creative | G20: RA Nor 3338W (220Kg) | H20: 1 | I20: =VLOOKUP(F20,'Set up'!$A$2:$C$70,3,FALSE) -> Cash | J20: =VLOOKUP(F20,'Set up'!$A$2:$D$70,4,FALSE) -> 0 | K20: =A20+J20 -> 44053 | L20: =MONTH(K20) -> 8 | M20: =YEAR(K20) -> 2020 | N20: 1496 | O20: =SUM(-N20) -> -1496 | P20: =SUM(N20+O20) -> 0 | Q20: =SUM(Q19+N20) -> 21752.5 | R20: =VLOOKUP(F20,'Set up'!$A$2:$E$70,5,FALSE) -> Chq | S20: Chq 10/8
A21: 44053 | B21: =MONTH(A21) -> 8 | C21: =YEAR(A21) -> 2020 | D21: INV2020/00000012 | E21: =VLOOKUP(F21,'Set up'!$A$2:$C$70,2,FALSE) -> C00000005 | F21: Artscene Creative | G21: RA Butanox M50 (5Kg) | H21: 1 | I21: =VLOOKUP(F21,'Set up'!$A$2:$C$70,3,FALSE) -> Cash | J21: =VLOOKUP(F21,'Set up'!$A$2:$D$70,4,FALSE) -> 0 | K21: =A21+J21 -> 44053 | L21: =MONTH(K21) -> 8 | M21: =YEAR(K21) -> 2020 | N21: 90 | O21: =SUM(-N21) -> -90 | P21: =SUM(N21+O21) -> 0 | Q21: =SUM(Q20+N21) -> 21842.5 | R21: =VLOOKUP(F21,'Set up'!$A$2:$E$70,5,FALSE) -> Chq | S21: Chq 10/8
A22: 44053 | B22: =MONTH(A22) -> 8 | C22: =YEAR(A22) -> 2020 | D22: INV2020/00000013 | E22: =VLOOKUP(F22,'Set up'!$A$2:$C$70,2,FALSE) -> C00000003 | F22: Pandian Art Gallery Manufacturing | G22: RA Nor 3338W (220Kg) | H22: 2 | I22: =VLOOKUP(F22,'Set up'!$A$2:$C$70,3,FALSE) -> 45 | J22: =VLOOKUP(F22,'Set up'!$A$2:$D$70,4,FALSE) -> 45 | K22: =A22+J22 -> 44098 | L22: =MONTH(K22) -> 9 | M22: =YEAR(K22) -> 2020 | N22: 3036 | O22: =SUM(-N22) -> -3036 | P22: =SUM(N22+O22) -> 0 | Q22: =SUM(Q21+N22) -> 24878.5 | R22: =VLOOKUP(F22,'Set up'!$A$2:$E$70,5,FALSE) -> PD Chq | S22: PD chq 13/9, RM1,700/- & 20/9, RM1,706/-
A23: 44053 | B23: =MONTH(A23) -> 8 | C23: =YEAR(A23) -> 2020 | D23: INV2020/00000013 | E23: =VLOOKUP(F23,'Set up'!$A$2:$C$70,2,FALSE) -> C00000003 | F23: Pandian Art Gallery Manufacturing | G23: RA Butanox M50 (5Kg) | H23: 4 | I23: =VLOOKUP(F23,'Set up'!$A$2:$C$70,3,FALSE) -> 45 | J23: =VLOOKUP(F23,'Set up'!$A$2:$D$70,4,FALSE) -> 45 | K23: =A23+J23 -> 44098 | L23: =MONTH(K23) -> 9 | M23: =YEAR(K23) -> 2020 | N23: 370 | O23: =SUM(-N23) -> -370 | P23: =SUM(N23+O23) -> 0 | Q23: =SUM(Q22+N23) -> 25248.5 | R23: =VLOOKUP(F23,'Set up'!$A$2:$E$70,5,FALSE) -> PD Chq | S23: PD chq 13/9, RM1,700/- & 20/9, RM1,706/-
A24: 44055 | B24: =MONTH(A24) -> 8 | C24: =YEAR(A24) -> 2020 | D24: INV2020/00000014 | E24: =VLOOKUP(F24,'Set up'!$A$2:$C$70,2,FALSE) -> C00000001 | F24: Kelnico Marketing | G24: RA Nor 3338W (220Kg) | H24: 1 | I24: =VLOOKUP(F24,'Set up'!$A$2:$C$70,3,FALSE) -> Cash | J24: =VLOOKUP(F24,'Set up'!$A$2:$D$70,4,FALSE) -> 0 | K24: =A24+J24 -> 44055 | L24: =MONTH(K24) -> 8 | M24: =YEAR(K24) -> 2020 | N24: 1496 | O24: =SUM(-N24) -> -1496 | P24: =SUM(N24+O24) -> 0 | Q24: =SUM(Q23+N24) -> 26744.5 | R24: =VLOOKUP(F24,'Set up'!$A$2:$E$70,5,FALSE) -> Trsf | S24: Trsf 23/8
A25: 44055 | B25: =MONTH(A25) -> 8 | C25: =YEAR(A25) -> 2020 | D25: INV2020/00000014 | E25: =VLOOKUP(F25,'Set up'!$A$2:$C$70,2,FALSE) -> C00000001 | F25: Kelnico Marketing | G25: RA CSM 450 GSM JUSHI 37kg 79m(L) X 1040mm(W) | H25: 4 | I25: =VLOOKUP(F25,'Set up'!$A$2:$C$70,3,FALSE) -> Cash | J25: =VLOOKUP(F25,'Set up'!$A$2:$D$70,4,FALSE) -> 0 | K25: =A25+J25 -> 44055 | L25: =MONTH(K25) -> 8 | M25: =YEAR(K25) -> 2020 | N25: 962 | O25: =SUM(-N25) -> -962 | P25: =SUM(N25+O25) -> 0 | Q25: =SUM(Q24+N25) -> 27706.5 | R25: =VLOOKUP(F25,'Set up'!$A$2:$E$70,5,FALSE) -> Trsf | S25: Trsf 23/8
A26: 44055 | B26: =MONTH(A26) -> 8 | C26: =YEAR(A26) -> 2020 | D26: INV2020/00000014 | E26: =VLOOKUP(F26,'Set up'!$A$2:$C$70,2,FALSE) -> C00000001 | F26: Kelnico Marketing | G26: RC Woven Roving E-800 40Kg 1000mm | H26: 2 | I26: =VLOOKUP(F26,'Set up'!$A$2:$C$70,3,FALSE) -> Cash | J26: =VLOOKUP(F26,'Set up'!$A$2:$D$70,4,FALSE) -> 0 | K26: =A26+J26 -> 44055 | L26: =MONTH(K26) -> 8 | M26: =YEAR(K26) -> 2020 | N26: 464 | O26: =SUM(-N26) -> -464 | P26: =SUM(N26+O26) -> 0 | Q26: =SUM(Q25+N26) -> 28170.5 | R26: =VLOOKUP(F26,'Set up'!$A$2:$E$70,5,FALSE) -> Trsf | S26: Trsf 23/8
A27: 44056 | B27: =MONTH(A27) -> 8 | C27: =YEAR(A27) -> 2020 | D27: INV2020/00000015 | E27: =VLOOKUP(F27,'Set up'!$A$2:$C$70,2,FALSE) -> C00000001 | F27: Kelnico Marketing | G27: RA Gelcoat GS-S ISO (20kg) | H27: 4 | I27: =VLOOKUP(F27,'Set up'!$A$2:$C$70,3,FALSE) -> Cash | J27: =VLOOKUP(F27,'Set up'!$A$2:$D$70,4,FALSE) -> 0 | K27: =A27+J27 -> 44056 | L27: =MONTH(K27) -> 8 | M27: =YEAR(K27) -> 2020 | N27: 960 | O27: =SUM(-N27) -> -960 | P27: =SUM(N27+O27) -> 0 | Q27: =SUM(Q26+N27) -> 29130.5 | R27: =VLOOKUP(F27,'Set up'!$A$2:$E$70,5,FALSE) -> Trsf | S27: Trsf 23/8
A28: 44062 | B28: =MONTH(A28) -> 8 | C28: =YEAR(A28) -> 2020 | D28: INV2020/00000016 | E28: =VLOOKUP(F28,'Set up'!$A$2:$C$70,2,FALSE) -> C00000003 | F28: Pandian Art Gallery Manufacturing | G28: RA CSM 450 GSM 54kg 64m(L) X 1860mm(W) | H28: 1 | I28: =VLOOKUP(F28,'Set up'!$A$2:$C$70,3,FALSE) -> 45 | J28: =VLOOKUP(F28,'Set up'!$A$2:$D$70,4,FALSE) -> 45 | K28: =A28+J28 -> 44107 | L28: =MONTH(K28) -> 10 | M28: =YEAR(K28) -> 2020 | N28: 367.2 | O28: =SUM(-N28) -> -367.2 | P28: =SUM(N28+O28) -> 0 | Q28: =SUM(Q27+N28) -> 29497.7 | R28: =VLOOKUP(F28,'Set up'!$A$2:$E$70,5,FALSE) -> PD Chq | S28: PD Chq 27/9, RM1,270.20
... A41: 44068 | B41: =MONTH(A41) -> 8 | C41: =YEAR(A41) -> 2020 | D41: INV2020/00000022 | E41: =VLOOKUP(F41,'Set up'!$A$2:$C$70,2,FALSE) -> C00000001 | F41: Kelnico Marketing | G41: RA Nor 3338W (220Kg) | H41: 1 | I41: =VLOOKUP(F41,'Set up'!$A$2:$C$70,3,FALSE) -> Cash | J41: =VLOOKUP(F41,'Set up'!$A$2:$D$70,4,FALSE) -> 0 | K41: =A41+J41 -> 44068 | L41: =MONTH(K41) -> 8 | M41: =YEAR(K41) -> 2020 | N41: 1496 | O41: =SUM(-N41) -> -1496 | P41: =SUM(N41+O41) -> 0 | Q41: =SUM(Q40+N41) -> 41562.7 | R41: =VLOOKUP(F41,'Set up'!$A$2:$E$70,5,FALSE) -> Trsf | S41: Trsf 1/9/2020
A42: 44070 | B42: =MONTH(A42) -> 8 | C42: =YEAR(A42) -> 2020 | D42: INV2020/00000023 | E42: =VLOOKUP(F42,'Set up'!$A$2:$C$70,2,FALSE) -> C00000010 | F42: Yew Seng Gardening Supply Sdn Bhd | G42: RA Nor 3338W (220Kg) | H42: 4 | I42: =VLOOKUP(F42,'Set up'!$A$2:$C$70,3,FALSE) -> 120 | J42: =VLOOKUP(F42,'Set up'!$A$2:$D$70,4,FALSE) -> 120 | K42: =A42+J42 -> 44190 | L42: =MONTH(K42) -> 12 | M42: =YEAR(K42) -> 2020 | N42: 5280 | O42: -5280 | P42: =SUM(N42+O42) -> 0 | Q42: =SUM(Q41+N42) -> 46842.7 | R42: =VLOOKUP(F42,'Set up'!$A$2:$E$70,5,FALSE) -> Trsf | S42: Trsf 23/12/2020
A43: 44070 | B43: =MONTH(A43) -> 8 | C43: =YEAR(A43) -> 2020 | D43: INV2020/00000023 | E43: =VLOOKUP(F43,'Set up'!$A$2:$C$70,2,FALSE) -> C00000010 | F43: Yew Seng Gardening Supply Sdn Bhd | G43: RA CSM 450 GSM JUSHI 37kg 79m(L) X 1040mm(W) | H43: 2 | I43: =VLOOKUP(F43,'Set up'!$A$2:$C$70,3,FALSE) -> 120 | J43: =VLOOKUP(F43,'Set up'!$A$2:$D$70,4,FALSE) -> 120 | K43: =A43+J43 -> 44190 | L43: =MONTH(K43) -> 12 | M43: =YEAR(K43) -> 2020 | N43: 444 | O43: -444 | P43: =SUM(N43+O43) -> 0 | Q43: =SUM(Q42+N43) -> 47286.7 | R43: =VLOOKUP(F43,'Set up'!$A$2:$E$70,5,FALSE) -> Trsf | S43: Trsf 23/12/2020
A44: 44070 | B44: =MONTH(A44) -> 8 | C44: =YEAR(A44) -> 2020 | D44: INV2020/00000023 | E44: =VLOOKUP(F44,'Set up'!$A$2:$C$70,2,FALSE) -> C00000010 | F44: Yew Seng Gardening Supply Sdn Bhd | G44: RA Talcum Powder (25kg) | H44: 5 | I44: =VLOOKUP(F44,'Set up'!$A$2:$C$70,3,FALSE) -> 120 | J44: =VLOOKUP(F44,'Set up'!$A$2:$D$70,4,FALSE) -> 120 | K44: =A44+J44 -> 44190 | L44: =MONTH(K44) -> 12 | M44: =YEAR(K44) -> 2020 | N44: 275 | O44: -275 | P44: =SUM(N44+O44) -> 0 | Q44: =SUM(Q43+N44) -> 47561.7 | R44: =VLOOKUP(F44,'Set up'!$A$2:$E$70,5,FALSE) -> Trsf | S44: Trsf 23/12/2020
A45: 44070 | B45: =MONTH(A45) -> 8 | C45: =YEAR(A45) -> 2020 | D45: INV2020/00000023 | E45: =VLOOKUP(F45,'Set up'!$A$2:$C$70,2,FALSE) -> C00000010 | F45: Yew Seng Gardening Supply Sdn Bhd | G45: RA Butanox M50 (5kg) | H45: 4 | I45: =VLOOKUP(F45,'Set up'!$A$2:$C$70,3,FALSE) -> 120 | J45: =VLOOKUP(F45,'Set up'!$A$2:$D$70,4,FALSE) -> 120 | K45: =A45+J45 -> 44190 | L45: =MONTH(K45) -> 12 | M45: =YEAR(K45) -> 2020 | N45: 360 | O45: -360 | P45: =SUM(N45+O45) -> 0 | Q45: =SUM(Q44+N45) -> 47921.7 | R45: =VLOOKUP(F45,'Set up'!$A$2:$E$70,5,FALSE) -> Trsf | S45: Trsf 23/12/2020
A46: 44070 | B46: =MONTH(A46) -> 8 | C46: =YEAR(A46) -> 2020 | D46: INV2020/00000023 | E46: =VLOOKUP(F46,'Set up'!$A$2:$C$70,2,FALSE) -> C00000010 | F46: Yew Seng Gardening Supply Sdn Bhd | G46: RA Bosny Wax (15kg) | H46: 1 | I46: =VLOOKUP(F46,'Set up'!$A$2:$C$70,3,FALSE) -> 120 | J46: =VLOOKUP(F46,'Set up'!$A$2:$D$70,4,FALSE) -> 120 | K46: =A46+J46 -> 44190 | L46: =MONTH(K46) -> 12 | M46: =YEAR(K46) -> 2020 | N46: 375 | O46: -375 | P46: =SUM(N46+O46) -> 0 | Q46: =SUM(Q45+N46) -> 48296.7 | R46: =VLOOKUP(F46,'Set up'!$A$2:$E$70,5,FALSE) -> Trsf | S46: Trsf 23/12/2020
A47: 44075 | B47: =MONTH(A47) -> 9 | C47: =YEAR(A47) -> 2020 | D47: INV2020/00000024 | E47: =VLOOKUP(F47,'Set up'!$A$2:$C$70,2,FALSE) -> C00000008 | F47: Wonderland Design Productions Studio | G47: RA Resin 3317AW (220Kg) | H47: 2 | I47: =VLOOKUP(F47,'Set up'!$A$2:$C$70,3,FALSE) -> Cash | J47: =VLOOKUP(F47,'Set up'!$A$2:$D$70,4,FALSE) -> 0 | K47: =A47+J47 -> 44075 | L47: =MONTH(K47) -> 9 | M47: =YEAR(K47) -> 2020 | N47: 2948 | O47: =SUM(-N47) -> -2948 | P47: =SUM(N47+O47) -> 0 | Q47: =SUM(Q46+N47) -> 51244.7 | R47: =VLOOKUP(F47,'Set up'!$A$2:$E$70,5,FALSE) -> Trsf | S47: Trsf 7/9/2020
A48: 44075 | B48: =MONTH(A48) -> 9 | C48: =YEAR(A48) -> 2020 | D48: INV2020/00000024 | E48: =VLOOKUP(F48,'Set up'!$A$2:$C$70,2,FALSE) -> C00000008 | F48: Wonderland Design Productions Studio | G48: RA Gelcoat GP-H (20kg) | H48: 4 | I48: =VLOOKUP(F48,'Set up'!$A$2:$C$70,3,FALSE) -> Cash | J48: =VLOOKUP(F48,'Set up'!$A$2:$D$70,4,FALSE) -> 0 | K48: =A48+J48 -> 44075 | L48: =MONTH(K48) -> 9 | M48: =YEAR(K48) -> 2020 | N48: 840 | O48: =SUM(-N48) -> -840 | P48: =SUM(N48+O48) -> 0 | Q48: =SUM(Q47+N48) -> 52084.7 | R48: =VLOOKUP(F48,'Set up'!$A$2:$E$70,5,FALSE) -> Trsf | S48: Trsf 7/9/2020
A49: 44075 | B49: =MONTH(A49) -> 9 | C49: =YEAR(A49) -> 2020 | D49: INV2020/00000024 | E49: =VLOOKUP(F49,'Set up'!$A$2:$C$70,2,FALSE) -> C00000008 | F49: Wonderland Design Productions Studio | G49: RA Butanox M50 (5kg) | H49: 2 | I49: =VLOOKUP(F49,'Set up'!$A$2:$C$70,3,FALSE) -> Cash | J49: =VLOOKUP(F49,'Set up'!$A$2:$D$70,4,FALSE) -> 0 | K49: =A49+J49 -> 44075 | L49: =MONTH(K49) -> 9 | M49: =YEAR(K49) -> 2020 | N49: 180 | O49: =SUM(-N49) -> -180 | P49: =SUM(N49+O49) -> 0 | Q49: =SUM(Q48+N49) -> 52264.7 | R49: =VLOOKUP(F49,'Set up'!$A$2:$E$70,5,FALSE) -> Trsf | S49: Trsf 7/9/2020
A50: 44076 | B50: =MONTH(A50) -> 9 | C50: =YEAR(A50) -> 2020 | D50: INV2020/00000025 | E50: =VLOOKUP(F50,'Set up'!$A$2:$C$70,2,FALSE) -> C00000001 | F50: Kelnico Marketing | G50: RA Silicone Rubber (25Kg) | H50: 1 | I50: =VLOOKUP(F50,'Set up'!$A$2:$C$70,3,FALSE) -> Cash | J50: =VLOOKUP(F50,'Set up'!$A$2:$D$70,4,FALSE) -> 0 | K50: =A50+J50 -> 44076 | L50: =MONTH(K50) -> 9 | M50: =YEAR(K50) -> 2020 | N50: 1250 | O50: =SUM(-N50) -> -1250 | P50: =SUM(N50+O50) -> 0 | Q50: =SUM(Q49+N50) -> 53514.7 | R50: =VLOOKUP(F50,'Set up'!$A$2:$E$70,5,FALSE) -> Trsf | S50: Trsf 5/9/2020 | T50: Delived on 3/9/2020
A51: 44079 | B51: =MONTH(A51) -> 9 | C51: =YEAR(A51) -> 2020 | D51: INV2020/00000026 | E51: =VLOOKUP(F51,'Set up'!$A$2:$C$70,2,FALSE) -> C00000001 | F51: Kelnico Marketing | G51: RA Resin 3317AW (220Kg) | H51: 1 | I51: =VLOOKUP(F51,'Set up'!$A$2:$C$70,3,FALSE) -> Cash | J51: =VLOOKUP(F51,'Set up'!$A$2:$D$70,4,FALSE) -> 0 | K51: =A51+J51 -> 44079 | L51: =MONTH(K51) -> 9 | M51: =YEAR(K51) -> 2020 | N51: 1496 | O51: =SUM(-N51) -> -1496 | P51: =SUM(N51+O51) -> 0 | Q51: =SUM(Q50+N51) -> 55010.7 | R51: =VLOOKUP(F51,'Set up'!$A$2:$E$70,5,FALSE) -> Trsf | S51: Trsf 5/9/2020
A52: 44079 | B52: =MONTH(A52) -> 9 | C52: =YEAR(A52) -> 2020 | D52: INV2020/00000026 | E52: =VLOOKUP(F52,'Set up'!$A$2:$C$70,2,FALSE) -> C00000001 | F52: Kelnico Marketing | G52: RA CSM 450 GSM JUSHI 37kg 79m(L) X 1040mm(W) | H52: 4 | I52: =VLOOKUP(F52,'Set up'!$A$2:$C$70,3,FALSE) -> Cash | J52: =VLOOKUP(F52,'Set up'!$A$2:$D$70,4,FALSE) -> 0 | K52: =A52+J52 -> 44079 | L52: =MONTH(K52) -> 9 | M52: =YEAR(K52) -> 2020 | N52: 962 | O52: =SUM(-N52) -> -962 | P52: =SUM(N52+O52) -> 0 | Q52: =SUM(Q51+N52) -> 55972.7 | R52: =VLOOKUP(F52,'Set up'!$A$2:$E$70,5,FALSE) -> Trsf | S52: Trsf 5/9/2020
...

Sheet Set up
A1: Customer Name | B1: Customer Code | C1: Payment Term | D1: Term | E1: Payment mode
A2: Kelnico Marketing | B2: C00000001 | C2: Cash | D2: 0 | E2: Trsf
A3: Sley | B3: C00000002 | C3: Cash | D3: 0 | E3: Chq
A4: Pandian Art Gallery Manufacturing | B4: C00000003 | C4: 45 | D4: 45 | E4: PD Chq
A5: Siew Min Lorry Sdn Bhd | B5: C00000004 | C5: 120 | D5: 120 | E5: Chq
A6: Artscene Creative | B6: C00000005 | C6: Cash | D6: 0 | E6: Chq
A7: Perniagaan Fibra Sahih | B7: C00000006 | C7: Cash | D7: 0 | E7: Chq
A8: Chin Fibreglass (M) Sdn Bhd | B8: C00000007 | C8: Cash | D8: 0 | E8: Trsf
A9: Wonderland Design Productions Studio | B9: C00000008 | C9: Cash | D9: 0 | E9: Trsf
A10: JMC Steel Engineering Sdn Bhd | B10: C00000009 | C10: 60 | D10: 60 | E10: Chq
A11: Yew Seng Gardening Supply Sdn Bhd | B11: C00000010 | C11: 120 | D11: 120 | E11: Trsf
A12: JT Johan Sdn Bhd | B12: C00000011 | C12: Cash | D12: 0 | E12: Trsf
A13: Cash - Hamdan | B13: C00000012 | C13: Cash | D13: 0 | E13: Cash
A14: Cash - PMC Sdn Bhd | B14: C00000013a | C14: Cash | D14: 0 | E14: Chq
A15: Protech Master Coach Sdn Bhd | B15: C00000013 | C15: Cash | D15: 0 | E15: Chq
A16: IK Fibre Glass Enterprise | B16: C00000014 | C16: Cash | D16: 0 | E16: Cash
A17: S&J Business Solutions | B17: C00000015 | C17: Cash | D17: 0 | E17: Trsf
A18: Win Fiber Sdn Bhd | B18: C00000016 | C18: Cash | D18: 0 | E18: Trsf
A19: Aumada Energy & Technologies (M) Sdn Bhd | B19: C00000017 | C19: Cash | D19: 0 | E19: Trsf
A20: Living Divani (M) Sdn Bhd | B20: C00000018 | C20: Cash | D20: 0 | E20: Trsf
A21: Desuki Affela Empire Enterprise | B21: C00000019 | C21: Cash | D21: 0 | E21: Trsf
A22: WSK Tanks Sdn Bhd | B22: C00000020 | C22: Cash | D22: 0 | E22: Trsf
A23: KT Profesional Fiber | B23: C00000021 | C23: Cash | D23: 0 | E23: PD Chq
... A39: Choi Fook Sing Enterprise Sdn Bhd | B39: C00000036 | C39: Cash | D39: 0 | E39: Trsf
A40: Suntruck Sdn Bhd | B40: C00000037 | C40: 30 | D40: 30 | E40: Chq
A41: WSA Engineering Sdn Bhd | B41: C00000038 | C41: Cash | D41: 0 | E41: Trsf
A42: Bestway Bina Sdn Bhd | B42: C00000039 | C42: Cash | D42: 0 | E42: Trsf
A43: Dynamic Builders Trading | B43: C00000040 | C43: Cash | D43: 0 | E43: Cash
A44: Airebus Sdn Bhd | B44: C00000041 | C44: Cash | D44: 0 | E44: Trsf
A45: Welltech (M) Sdn Bhd | B45: C00000042 | C45: Cash | D45: 0 | E45: Trsf
A46: RBD World Wide Sdn Bhd | B46: C00000043 | C46: Cash | D46: 0 | E46: Trsf
A47: Cash - Encik Razzak | B47: C00000044 | C47: Cash | D47: 0 | E47: Cash
A48: Kelnico Sdn Bhd | B48: C00000045 | C48: Cash | D48: 0 | E48: Trsf
A49: Berkat Fibreglass | B49: C00000046 | C49: Cash | D49: 0 | E49: Cash
A50: KAD Builders Sdn Bhd | B50: C00000047 | C50: Cash | D50: 0 | E50: Cash
A51: Cash - Encik Mohammad Mongal | B51: C00000048 | C51: Cash | D51: 0 | E51: Cash
A52: DOB Engineering Solutions | B52: C00000049 | C52: Cash | D52: 0 | E52: Cash
... A67: Cash - Encik Alang | B67: C00000064 | C67: Cash | D67: 0 | E67: Cash

Sheet Customer Payment Term
A1: Customer Payment Term | V1: Customer Payment Term
A4: Sum of Sales Amount | C4: Term | V4: Sum of Sales Amount | W4: Year (Sales) | X4: Term
A5: Year (Sales) | B5: Customer Name | C5: 0 | D5: 45 | E5: 60 | F5: 120 | G5: #N/A | H5: 30 | I5: Grand Total | W5: 2019 | X5: 2019 Total | Y5: 2020 | AD5: 2020 Total | AE5: 2021 | AJ5: 2021 Total | AK5: 2022 | AP5: 2022 Total | AQ5: Grand Total
A6: 2019 | B6: Kelnico Marketing | C6: 2973 | I6: 2973 | V6: Customer Name | W6: 0 | Y6: 0 | Z6: 45 | AA6: 60 | AB6: 120 | AC6: #N/A | AE6: 0 | AF6: 45 | AG6: 60 | AH6: 120 | AI6: #N/A | AK6: 0 | AL6: 45 | AM6: 60 | AN6: 120 | AO6: #N/A
A7: 2019 Total | C7: 2973 | I7: 2973 | V7: Artscene Creative | Y7: 9334 | AD7: 9334 | AE7: 13661.4 | AJ7: 13661.4 | AQ7: 22995.4
A8: 2020 | B8: Artscene Creative | C8: 9334 | I8: 9334 | V8: Chin Fibreglass (M) Sdn Bhd | Y8: 5606 | AD8: 5606 | AQ8: 5606
B9: Chin Fibreglass (M) Sdn Bhd | C9: 5606 | I9: 5606 | V9: JMC Steel Engineering Sdn Bhd | AA9: 4191.2 | AD9: 4191.2 | AG9: 23646.6 | AJ9: 23646.6 | AM9: 37167.5 | AP9: 37167.5 | AQ9: 65005.3
B10: JMC Steel Engineering Sdn Bhd | E10: 4191.2 | I10: 4191.2 | V10: Kelnico Marketing | W10: 2973 | X10: 2973 | Y10: 34235 | AD10: 34235 | AE10: 22043 | AJ10: 22043 | AK10: 23044 | AP10: 23044 | AQ10: 82295
B11: Kelnico Marketing | C11: 34235 | I11: 34235 | V11: Pandian Art Gallery Manufacturing | Z11: 28025.7 | AD11: 28025.7 | AF11: 34482.5 | AJ11: 34482.5 | AL11: 43991 | AP11: 43991 | AQ11: 106499.2
B12: Pandian Art Gallery Manufacturing | D12: 28025.7 | I12: 28025.7 | V12: Perniagaan Fibra Sahih | Y12: 4008 | AD12: 4008 | AE12: 240 | AJ12: 240 | AK12: 11828.5 | AP12: 11828.5 | AQ12: 16076.5
B13: Perniagaan Fibra Sahih | C13: 4008 | I13: 4008 | V13: Siew Min Lorry Sdn Bhd | AB13: 52285.6 | AD13: 52285.6 | AH13: 85763 | AJ13: 85763 | AN13: 101459.4 | AP13: 101459.4 | AQ13: 239508
B14: Siew Min Lorry Sdn Bhd | F14: 52285.6 | I14: 52285.6 | V14: Sley | Y14: 2067 | AD14: 2067 | AE14: 3432 | AJ14: 3432 | AQ14: 5499
B15: Sley | C15: 2067 | I15: 2067 | V15: Wonderland Design Productions Studio | Y15: 9082 | AD15: 9082 | AE15: 8568 | AJ15: 8568 | AQ15: 17650
B16: Wonderland Design Productions Studio | C16: 9082 | I16: 9082 | V16: Yew Seng Gardening Supply Sdn Bhd | AB16: 50446 | AD16: 50446 | AH16: 140677.6 | AJ16: 140677.6 | AN16: 206833.5 | AP16: 206833.5 | AQ16: 397957.1
B17: Yew Seng Gardening Supply Sdn Bhd | F17: 50446 | I17: 50446 | V17: JT Johan Sdn Bhd | Y17: 1082.8 | AD17: 1082.8 | AQ17: 1082.8
B18: JT Johan Sdn Bhd | C18: 1082.8 | I18: 1082.8 | V18: Cash - Muhammad Syahin Bin | AC18: 799.2 | AD18: 799.2 | AQ18: 799.2
B19: Cash - Muhammad Syahin Bin | G19: 799.2 | I19: 799.2 | V19: Cash - PMC | AI19: 3070 | AJ19: 3070 | AQ19: 3070
A20: 2020 Total | C20: 65414.8 | D20: 28025.7 | E20: 4191.2 | F20: 102731.6 | G20: 799.2 | I20: 201162.5 | V20: IK Fibre Glass Enterprise | AE20: 8402 | AJ20: 8402 | AQ20: 8402
A21: 2021 | B21: Artscene Creative | C21: 13661.4 | I21: 13661.4 | V21: S&J Business Solutions | AE21: 4247 | AJ21: 4247 | AQ21: 4247
B22: JMC Steel Engineering Sdn Bhd | E22: 23646.6 | I22: 23646.6 | V22: Win Fiber Sdn Bhd | AE22: 10807.25 | AJ22: 10807.25 | AQ22: 10807.25
B23: Kelnico Marketing | C23: 22043 | I23: 22043 | V23: Living Divani (M) Sdn Bhd | AE23: 9592 | AJ23: 9592 | AQ23: 9592
B24: Pandian Art Gallery Manufacturing | D24: 34482.5 | I24: 34482.5 | V24: Desuki Affela Empire Enterprise | AE24: 31182 | AJ24: 31182 | AK24: 76338.9 | AP24: 76338.9 | AQ24: 107520.9
B25: Perniagaan Fibra Sahih | C25: 240 | I25: 240 | V25: WSK Tanks Sdn Bhd | AE25: 204219.6 | AJ25: 204219.6 | AK25: 583746.3 | AP25: 583746.3 | AQ25: 787965.9
B26: Siew Min Lorry Sdn Bhd | F26: 85763 | I26: 85763 | V26: Cash - En Mat | AI26: 240 | AJ26: 240 | AQ26: 240
B27: Sley | C27: 3432 | I27: 3432 | V27: KT Profesional Fiber | AE27: 2024 | AJ27: 2024 | AK27: 79757.3 | AP27: 79757.3 | AQ27: 81781.3
B28: Wonderland Design Productions Studio | C28: 8568 | I28: 8568 | V28: SF Engineering Solution | AK28: 23064.7 | AP28: 23064.7 | AQ28: 23064.7
B29: Yew Seng Gardening Supply Sdn Bhd | F29: 140677.6 | I29: 140677.6 | V29: Bestway Engineering Solutions | AK29: 26300.5 | AP29: 26300.5 | AQ29: 26300.5
B30: Cash - PMC | G30: 3070 | I30: 3070 | V30: Worldwide Competence Sdn Bhd | AK30: 15169 | AP30: 15169 | AQ30: 15169
B31: IK Fibre Glass Enterprise | C31: 8402 | I31: 8402 | V31: LLL Automotive Sdn Bhd | AK31: 1238 | AP31: 1238 | AQ31: 1238
B32: S&J Business Solutions | C32: 4247 | I32: 4247 | V32: Megapower Service | AK32: 6907.6 | AP32: 6907.6 | AQ32: 6907.6
B33: Win Fiber Sdn Bhd | C33: 10807.25 | I33: 10807.25 | V33: Transform Star Sdn Bhd | AK33: 58888.8 | AP33: 58888.8 | AQ33: 58888.8
B34: Living Divani (M) Sdn Bhd | C34: 9592 | I34: 9592 | V34: CANCELLED INVOICE | AO34: 0 | AP34: 0 | AQ34: 0
B35: Desuki Affela Empire Enterprise | C35: 31182 | I35: 31182 | V35: Cash - Vinz Yew Kok Wah | AK35: 4447.5 | AP35: 4447.5 | AQ35: 4447.5
B36: WSK Tanks Sdn Bhd | C36: 204219.6 | I36: 204219.6 | V36: Cash - Big Jackfruit Trading | AK36: 1672.6 | AP36: 1672.6 | AQ36: 1672.6
B37: Cash - En Mat | G37: 240 | I37: 240 | V37: Hai Kee Hung Sdn Bhd | AK37: 4373 | AP37: 4373 | AQ37: 4373
B38: KT Profesional Fiber | C38: 2024 | I38: 2024 | V38: Cash - PMC Sdn Bhd | AE38: 26393.4 | AJ38: 26393.4 | AQ38: 26393.4
B39: Cash - PMC Sdn Bhd | C39: 26393.4 | I39: 26393.4 | V39: Aumada Energy & Technologies (M) Sdn Bhd | AE39: 855 | AJ39: 855 | AQ39: 855
B40: Aumada Energy & Technologies (M) Sdn Bhd | C40: 855 | I40: 855 | V40: Grand Total | W40: 2973 | X40: 2973 | Y40: 65414.8 | Z40: 28025.7 | AA40: 4191.2 | AB40: 102731.6 | AC40: 799.2 | AD40: 201162.5 | AE40: 345666.65 | AF40: 34482.5 | AG40: 23646.6 | AH40: 226440.6 | AI40: 3310 | AJ40: 633546.35 | AK40: 916776.7 | AL40: 43991 | AM40: 37167.5 | AN40: 308292.9 | AO40: 0 | AP40: 1306228.1 | AQ40: 2143910
A41: 2021 Total | C41: 345666.65 | D41: 34482.5 | E41: 23646.6 | F41: 226440.6 | G41: 3310 | I41: 633546.35
A42: 2022 | B42: JMC Steel Engineering Sdn Bhd | E42: 41800.3 | I42: 41800.3
...

Sheet Transport_by month (estimate)
A3: Period (Sales) | B3: Date | C3: Invoice No | D3: Customer Name | E3: Amount
A4: 12 | B4: 43822 | C4: INV2019/00000001 | D4: Kelnico Marketing | E4: 80
A5: 12 Total | E5: =SUM(E4) -> 80
A6: 6 | B6: 43984 | C6: INV2020/00000002 | D6: Kelnico Marketing | E6: 80
B7: 43993 | C7: INV2020/00000003 | D7: Sley | E7: 80
B8: 43999 | C8: INV2020/00000004 | D8: Kelnico Marketing | E8: 80
B9: 44004 | C9: INV2020/00000005 | D9: Pandian Art Gallery Manufacturing | E9: 80
A10: 6 Total | E10: =SUM(E6:E9) -> 320
A11: Total | E11: =SUM(E10,E5) -> 400
A14: Period (Sales) | B14: Date | C14: Invoice No | D14: Customer Name | E14: Amount
A15: 7 | B15: 44013 | C15: INV2020/00000006 | D15: Siew Min Lorry Sdn Bhd | E15: 80
B16: 44026 | C16: INV2020/00000007 | D16: Pandian Art Gallery Manufacturing | E16: 80
B17: 44027 | C17: INV2020/00000008 | D17: Kelnico Marketing | E17: 80
A18: 7 Total | E18: =SUM(E15:E17) -> 240
A19: 8 | B19: 44044 | C19: INV2020/00000009 | D19: Siew Min Lorry Sdn Bhd | E19: 80
B20: 44051 | C20: INV2020/00000010 | D20: Siew Min Lorry Sdn Bhd | E20: 80
C21: INV2020/00000011 | D21: Siew Min Lorry Sdn Bhd | E21: 80
B22: 44053 | C22: INV2020/00000012 | D22: Artscene Creative | E22: 80
C23: INV2020/00000013 | D23: Pandian Art Gallery Manufacturing | E23: 80
B24: 44055 | C24: INV2020/00000014 | D24: Kelnico Marketing | E24: 80
B25: 44056 | C25: INV2020/00000015 | D25: Kelnico Marketing | E25: 80
B26: 44062 | C26: INV2020/00000016 | D26: Pandian Art Gallery Manufacturing | E26: 80
C27: INV2020/00000017 | D27: Perniagaan Fibra Sahih | E27: 80
B28: 44065 | C28: INV2020/00000018 | D28: Chin Fibreglass (M) Sdn Bhd | E28: 80
C29: INV2020/00000019 | D29: Wonderland Design Productions Studio | E29: 80
B30: 44067 | C30: INV2020/00000020 | D30: Pandian Art Gallery Manufacturing | E30: 80
B31: 44068 | C31: INV2020/00000021 | D31: JMC Steel Engineering Sdn Bhd | E31: 80
C32: INV2020/00000022 | D32: Kelnico Marketing | E32: 80
B33: 44070 | C33: INV2020/00000023 | D33: Yew Seng Gardening Supply Sdn Bhd | E33: 80
A34: 8 Total | E34: =SUM(E19:E33) -> 1200
A35: 9 | B35: 44075 | C35: INV2020/00000024 | D35: Wonderland Design Productions Studio | E35: 80
B36: 44076 | C36: INV2020/00000025 | D36: Kelnico Marketing | E36: 80
B37: 44079 | C37: INV2020/00000026 | D37: Kelnico Marketing | E37: 80
B38: 44091 | C38: INV2020/00000027 | D38: Siew Min Lorry Sdn Bhd | E38: 80
C39: INV2020/00000028 | D39: Kelnico Marketing | E39: 80
B40: 44096 | C40: INV2020/00000029 | D40: Siew Min Lorry Sdn Bhd | E40: 80
B41: 44097 | C41: INV2020/00000030 | D41: Yew Seng Gardening Supply Sdn Bhd | E41: 80
C42: INV2020/00000031 | D42: Kelnico Marketing | E42: 80
B43: 44100 | C43: INV2020/00000032 | D43: Kelnico Marketing | E43: 80
A44: 9 Total | E44: =SUM(E35:E43) -> 720
...

Sheet Inv No with date
A1: Year (Sales) | B1: 2022
A3: Sum of Sales Amount
A4: Period (Sales) | B4: Invoice Date | C4: Invoice No | D4: Customer Name | E4: Total
A5: 3 | B5: 44625 | C5: INV00000209 | D5: KT Profesional Fiber | E5: 6301
B6: 44628 | C6: INV00000210 | D6: SF Engineering Solution | E6: 4873
C7: INV00000211 | D7: Yew Seng Gardening Supply Sdn Bhd | E7: 15280
B8: 44629 | C8: INV00000212 | D8: SF Engineering Solution | E8: 65
B9: 44631 | C9: INV00000213 | D9: Desuki Affela Empire Enterprise | E9: 6379.9
B10: 44632 | C10: INV00000214 | D10: SF Engineering Solution | E10: 390
C11: INV00000215 | D11: Perniagaan Fibra Sahih | E11: 2068
B12: 44634 | C12: INV00000216 | D12: WSK Tanks Sdn Bhd | E12: 3029
B13: 44635 | C13: INV00000217 | D13: Yew Seng Gardening Supply Sdn Bhd | E13: 14185
C14: INV00000218 | D14: WSK Tanks Sdn Bhd | E14: 11425
B15: 44637 | C15: INV00000219 | D15: Desuki Affela Empire Enterprise | E15: 315
B16: 44638 | C16: INV00000220 | D16: WSK Tanks Sdn Bhd | E16: 9888
B17: 44639 | C17: INV00000221 | D17: KT Profesional Fiber | E17: 8127.5
B18: 44641 | C18: INV00000222 | D18: Perniagaan Fibra Sahih | E18: 337.5
B19: 44643 | C19: INV00000223 | D19: WSK Tanks Sdn Bhd | E19: 8819
B20: 44645 | C20: INV00000224 | D20: WSK Tanks Sdn Bhd | E20: 14422
B21: 44649 | C21: INV00000225 | D21: Kelnico Marketing | E21: 3232
C22: INV00000226 | D22: WSK Tanks Sdn Bhd | E22: 7593
B23: 44651 | C23: INV00000227 | D23: Bestway Engineering Solutions | E23: 3555
A24: 3 Total | E24: 120284.9
A25: 4 | B25: 26/4/2022 | C25: INV00000250 | D25: Bestway Engineering Solutions | E25: 3799
B26: 44652 | C26: INV00000228 | D26: KT Profesional Fiber | E26: 6083.5
C27: INV00000229 | D27: WSK Tanks Sdn Bhd | E27: 9157.5
C28: INV00000230 | D28: SF Engineering Solution | E28: 3480
B29: 44656 | C29: INV00000231 | D29: WSK Tanks Sdn Bhd | E29: 10497.5
B30: 44659 | C30: INV00000232 | D30: Desuki Affela Empire Enterprise | E30: 6361.1
C31: INV00000233 | D31: Pandian Art Gallery Manufacturing | E31: 7316
B32: 44660 | C32: INV00000234 | D32: JMC Steel Engineering Sdn Bhd | E32: 5043
C33: INV00000235 | D33: WSK Tanks Sdn Bhd | E33: 8569.5
C34: INV00000236 | D34: Worldwide Competence Sdn Bhd | E34: 3881.5
B35: 44663 | C35: INV00000237 | D35: SF Engineering Solution | E35: 590
B36: 44664 | C36: INV00000238 | D36: Worldwide Competence Sdn Bhd | E36: 588
C37: INV00000239 | D37: WSK Tanks Sdn Bhd | E37: 10975.5
B38: 44665 | C38: INV00000240 | D38: KT Profesional Fiber | E38: 5746
B39: 44666 | C39: INV00000241 | D39: Worldwide Competence Sdn Bhd | E39: 2175
B40: 44667 | C40: INV00000242 | D40: WSK Tanks Sdn Bhd | E40: 10103.5
C41: INV00000243 | D41: Bestway Engineering Solutions | E41: 14088.5
...

Sheet Sales_by Inv No & by customer
A1: Year (Sales) | B1: 2022
D3: Values | N3: Sum of Sales Amount | P3: Year (Sales) | Q3: Period (Sales)
A4: Period (Sales) | B4: Invoice No | C4: Customer Name | D4: Sum of Sales Amount2 | E4: Sum of Collection | F4: Sum of Outstanding | P4: 2019 | Q4: 2019 Total | R4: 2020 | Y4: 2020 Total | Z4: 2021 | AJ4: 2021 Total | AK4: 2022 | AW4: 2022 Total | AX4: 2023 | BJ4: 2023 Total | BK4: 2024 | BS4: 2024 Total | BT4: Grand Total
A5: 6 | B5: INV00000278 | C5: WSK Tanks Sdn Bhd | D5: 12427 | E5: -12427 | F5: 0 | N5: Customer Name | O5: Invoice No | P5: 12 | R5: 6 | S5: 7 | T5: 8 | U5: 9 | V5: 10 | W5: 11 | X5: 12 | Z5: 6 | AA5: 9 | AB5: 10 | AC5: 11 | AD5: 12 | AE5: 1 | AF5: 2 | AG5: 3 | AH5: 4 | AI5: 5 | AK5: 6 | AL5: 7 | AM5: 8 | AN5: 9 | AO5: 10 | AP5: 11 | AQ5: 12 | AR5: 1 | AS5: 2 | AT5: 3 | AU5: 4 | AV5: 5 | AX5: 6 | AY5: 7 | AZ5: 8 | BA5: 9 | BB5: 10 | BC5: 11 | BD5: 12 | BE5: 1 | BF5: 2 | BG5: 3 | BH5: 4 | BI5: 5 | BK5: 6 | BL5: 7 | BM5: 8 | BN5: 1 | BO5: 2 | BP5: 3 | BQ5: 4 | BR5: 5
B6: INV00000279 | C6: SF Engineering Solution | D6: 2112 | E6: -2112 | F6: 0 | N6: Artscene Creative | O6: INV2020/00000012 | T6: 1586 | Y6: 1586 | BT6: 1586
B7: INV00000280 | C7: WSK Tanks Sdn Bhd | D7: 9000 | E7: -9000 | F7: 0 | O7: INV2020/00000033 | V7: 1496 | Y7: 1496 | BT7: 1496
B8: INV00000281 | C8: Kelnico Marketing | D8: 2356 | E8: -2356 | F8: 0 | O8: INV2020/00000042 | V8: 90 | Y8: 90 | BT8: 90
B9: INV00000282 | C9: Yew Seng Gardening Supply Sdn Bhd | D9: 12690 | E9: -12690 | F9: 0 | O9: INV2020/00000043 | V9: 1496 | Y9: 1496 | BT9: 1496
B10: INV00000283 | C10: SF Engineering Solution | D10: 2112 | E10: -2112 | F10: 0 | O10: INV2020/00000047 | V10: 1496 | Y10: 1496 | BT10: 1496
B11: INV00000284 | C11: KT Profesional Fiber | D11: 2746 | E11: -2746 | F11: 0 | O11: INV2020/00000050 | W11: 1630 | Y11: 1630 | BT11: 1630
B12: INV00000285 | C12: WSK Tanks Sdn Bhd | D12: 4950 | E12: -4950 | F12: 0 | O12: INV2020/00000056 | W12: 1540 | Y12: 1540 | BT12: 1540
B13: INV00000286 | C13: Bestway Engineering Solutions | D13: 2158 | E13: -2158 | F13: 0 | O13: INV2020/00000078 | AF13: 1750 | AJ13: 1750 | BT13: 1750
B14: INV00000287 | C14: JMC Steel Engineering Sdn Bhd | D14: 3960 | E14: -3960 | F14: 0 | O14: INV2020/00000081 | AF14: 225 | AJ14: 225 | BT14: 225
B15: INV00000288 | C15: Kelnico Marketing | D15: 3232 | E15: -3232 | F15: 0 | O15: INV00000103 | AI15: 1876 | AJ15: 1876 | BT15: 1876
B16: INV00000289 | C16: WSK Tanks Sdn Bhd | D16: 4431.5 | E16: -4431.5 | F16: 0 | O16: INV00000105 | AI16: 1826 | AJ16: 1826 | BT16: 1826
B17: INV00000290 | C17: Perniagaan Fibra Sahih | D17: 2068 | E17: -2068 | F17: 0 | O17: INV00000107 | AI17: 100 | AJ17: 100 | BT17: 100
B18: INV00000291 | C18: KT Profesional Fiber | D18: 3374.5 | E18: -3374.5 | F18: 0 | O18: INV00000113 | AA18: 1826 | AJ18: 1826 | BT18: 1826
B19: INV00000292 | C19: WSK Tanks Sdn Bhd | D19: 5889 | E19: -5889 | F19: 0 | O19: INV00000114 | AA19: 1926 | AJ19: 1926 | BT19: 1926
B20: INV00000293 | C20: Desuki Affela Empire Enterprise | D20: 6223.6 | E20: -6223.6 | F20: 0 | O20: INV00000122 | AA20: 1826 | AJ20: 1826 | BT20: 1826
B21: INV00000294 | C21: Yew Seng Gardening Supply Sdn Bhd | D21: 18515 | E21: -18515 | F21: 0 | O21: INV00000137 | AB21: 1926 | AJ21: 1926 | BT21: 1926
A22: 6 Total | D22: 98244.6 | E22: -98244.6 | F22: 0 | O22: INV00000150 | AC22: 380.4 | AJ22: 380.4 | BT22: 380.4
A23: 7 | B23: INV00000295 | C23: JMC Steel Engineering Sdn Bhd | D23: 1539 | E23: -1539 | F23: 0 | N23: Artscene Creative Total | T23: 1586 | V23: 4578 | W23: 3170 | Y23: 9334 | AA23: 5578 | AB23: 1926 | AC23: 380.4 | AF23: 1975 | AI23: 3802 | AJ23: 13661.4 | BT23: 22995.4
B24: INV00000296 | C24: Desuki Affela Empire Enterprise | D24: 5183.6 | E24: -5183.6 | F24: 0 | N24: Chin Fibreglass (M) Sdn Bhd | O24: INV2020/00000018 | T24: 2956 | Y24: 2956 | BT24: 2956
B25: INV00000297 | C25: WSK Tanks Sdn Bhd | D25: 12855.5 | E25: -12855.5 | F25: 0 | O25: INV2020/00000038 | V25: 2650 | Y25: 2650 | BT25: 2650
B26: INV00000298 | C26: Transform Star Sdn Bhd | D26: 8568.2 | E26: -8568.2 | F26: 0 | N26: Chin Fibreglass (M) Sdn Bhd Total | T26: 2956 | V26: 2650 | Y26: 5606 | BT26: 5606
B27: INV00000299 | C27: WSK Tanks Sdn Bhd | D27: 9153 | E27: -9153 | F27: 0 | N27: JMC Steel Engineering Sdn Bhd | O27: INV2020/00000021 | T27: 2552 | Y27: 2552 | BT27: 2552
B28: INV00000300 | C28: WSK Tanks Sdn Bhd | D28: 925.5 | E28: -925.5 | F28: 0 | O28: INV2020/00000051 | W28: 1231.2 | Y28: 1231.2 | BT28: 1231.2
B29: INV00000301 | C29: WSK Tanks Sdn Bhd | D29: 6625 | E29: -6625 | F29: 0 | O29: INV2020/00000060 | W29: 408 | Y29: 408 | BT29: 408
B30: INV00000302 | C30: Kelnico Marketing | D30: 4092 | E30: -4092 | F30: 0 | O30: INV00000088 | AG30: 6459.6 | AJ30: 6459.6 | BT30: 6459.6
B31: INV00000303 | C31: Yew Seng Gardening Supply Sdn Bhd | D31: 13445 | E31: -13445 | F31: 0 | O31: INV00000091 | AG31: 90 | AJ31: 90 | BT31: 90
B32: INV00000304 | C32: KT Profesional Fiber | D32: 2180 | E32: -2180 | F32: 0 | O32: INV00000100 | AH32: 7482 | AJ32: 7482 | BT32: 7482
B33: INV00000305 | C33: JMC Steel Engineering Sdn Bhd | D33: 4596.5 | E33: -4596.5 | F33: 0 | O33: INV00000109 | Z33: 3825 | AJ33: 3825 | BT33: 3825
A34: 7 Total | D34: 69163.3 | E34: -69163.3 | F34: 0 | O34: INV00000110 | Z34: 690 | AJ34: 690 | BT34: 690
A35: 8 | B35: INV00000306 | C35: Transform Star Sdn Bhd | D35: 12643.2 | E35: -12643 | F35: 0.2 | O35: INV00000135 | AB35: 5100 | AJ35: 5100 | BT35: 5100
B36: INV00000307 | C36: WSK Tanks Sdn Bhd | D36: 5268.6 | E36: -5268.6 | F36: 0 | O36: INV00000201 | AS36: 5940 | AW36: 5940 | BT36: 5940
B37: INV00000308 | C37: Kelnico Marketing | D37: 864 | E37: -864 | F37: 0 | O37: INV00000234 | AU37: 5043 | AW37: 5043 | BT37: 5043
B38: INV00000309 | C38: Megapower Service | D38: 2068 | E38: -2068 | F38: 0 | O38: INV00000260 | AV38: 5100 | AW38: 5100 | BT38: 5100
B39: INV00000310 | C39: WSK Tanks Sdn Bhd | D39: 4312.5 | E39: -4312.5 | F39: 0 | O39: INV00000287 | AK39: 3960 | AW39: 3960 | BT39: 3960
B40: INV00000311 | C40: CANCELLED INVOICE | D40: 0 | F40: 0 | O40: INV00000295 | AL40: 1539 | AW40: 1539 | BT40: 1539
B41: INV00000312 | C41: Siew Min Lorry Sdn Bhd | D41: 16536.7 | E41: -16536.7 | F41: 0 | O41: INV00000305 | AL41: 4596.5 | AW41: 4596.5 | BT41: 4596.5
...

Sheet Sales Qty_by product
A1: Year (Sales) | B1: 2024
A2: Period (Sales) | B2: 9
A4: Sum of Qty
A5: Product | B5: Total
A6: RA Butanox M50 (5Kg) | B6: 11
A7: RA Nor 3338W (220Kg) | B7: 2
A8: RE Frekote 770NC (1 Gallon) | B8: 1
A9: RH Bosny Wax (15kg) | B9: 1
A10: RM Resin 3317AW (220Kg) | B10: 2
A11: RM Pigment Super White (5Kg) | B11: 1
A12: RD Brush 3" (12Pc) | B12: 8
A13: RM Pigment Paste Smooth Cream M19 (25kg) | B13: 5
A14: RA Mepoxe (5kg) | B14: 13
A15: RA Resin 3338W (220kg) | B15: 12
A16: RM Resin 3338W (220kg) | B16: 1
A17: RM CSM 450 1860mm(W) (54kg) | B17: 2
... A32: Grand Total | B32: 353

Sheet Sales_by Inv No
E3: Values
A4: Year (Sales) | B4: Period (Sales) | C4: Invoice No | D4: Customer Name | E4: Sum of Sales Amount2 | F4: Sum of Collection | G4: Sum of Outstanding
A5: 2024 | B5: 8 | C5: INV00000934 | D5: Suntruck Sdn Bhd | E5: 8732.3 | F5: -8732.3 | G5: 0
C6: INV00000935 | D6: Welltech (M) Sdn Bhd | E6: 410 | F6: -410 | G6: 0
C7: INV00000936 | D7: Perniagaan Fibra Sahih | E7: 12250 | F7: -12250 | G7: 0
C8: INV00000937 | D8: Cash - Encik Razzak | E8: 2878 | F8: -2878 | G8: 0
C9: INV00000938 | D9: YL Professional Fiber Trading | E9: 2687.5 | F9: -2687.5 | G9: 0
C10: INV00000939 | D10: Yew Seng Gardening Supply Sdn Bhd | E10: 17177.6 | F10: -17177.6 | G10: 0
C11: INV00000940 | D11: Desuki Affela Empire Enterprise | E11: 2997.5 | G11: 2997.5
C12: INV00000941 | D12: Cash - Hamdan | E12: 1185 | F12: -1185 | G12: 0
C13: INV00000942 | D13: DOB Engineering Solutions | E13: 6210 | G13: 6210
C14: INV00000943 | D14: Welltech (M) Sdn Bhd | E14: 625 | F14: -625 | G14: 0
C15: INV00000944 | D15: Welltech (M) Sdn Bhd | E15: 26725 | F15: -26725 | G15: 0
C16: INV00000945 | D16: Megapower Service | E16: 2143 | F16: -2143 | G16: 0
C17: INV00000946 | D17: Pandian Art Gallery Manufacturing | E17: 2322 | F17: -2322 | G17: 0
C18: INV00000947 | D18: DOB Engineering Solutions | E18: 4195 | G18: 4195
C19: INV00000948 | D19: DOB Engineering Solutions | E19: 110 | G19: 110
C20: INV00000949 | D20: Welltech (M) Sdn Bhd | E20: 1000 | F20: -1000 | G20: 0
C21: INV00000950 | D21: DOB Engineering Solutions | E21: 250 | G21: 250
C22: INV00000951 | D22: Desuki Affela Empire Enterprise | E22: 1880 | G22: 1880
C23: INV00000952 | D23: DOB Engineering Solutions | E23: 180 | G23: 180
C24: INV00000953 | D24: Welltech (M) Sdn Bhd | E24: 125 | F24: -125 | G24: 0
C25: INV00000954 | D25: Welltech (M) Sdn Bhd | E25: 4734 | F25: -4734 | G25: 0
C26: INV00000955 | D26: DOB Engineering Solutions | E26: 175 | G26: 175
C27: INV00000956 | D27: Welltech (M) Sdn Bhd | E27: 187.5 | F27: -187.5 | G27: 0
C28: INV00000957 | D28: Welltech (M) Sdn Bhd | E28: 9269 | F28: -9269 | G28: 0
C29: INV00000958 | D29: Transform Star Sdn Bhd | E29: 8026.4 | G29: 8026.4
C30: INV00000959 | D30: Yew Seng Gardening Supply Sdn Bhd | E30: 881 | F30: -881 | G30: 0
C31: INV00000960 | D31: IK Fibre Glass Enterprise | E31: 207 | F31: -207 | G31: 0
C32: INV00000961 | D32: Desuki Affela Empire Enterprise | E32: 2772.5 | G32: 2772.5
C33: INV00000962 | D33: Welltech (M) Sdn Bhd | E33: 250 | F33: -250 | G33: 0
C34: INV00000963 | D34: Welltech (M) Sdn Bhd | E34: 9908 | F34: -9908 | G34: 0
C35: INV00000964 | D35: Yew Seng Gardening Supply Sdn Bhd | E35: 2450 | F35: -2450 | G35: 0
B36: 8 Total | E36: 132943.3 | F36: -106146.9 | G36: 26796.4
A37: 2024 Total | E37: 132943.3 | F37: -106146.9 | G37: 26796.4
A38: Grand Total | E38: 132943.3 | F38: -106146.9 | G38: 26796.4
